{"uuid": "5235e092-c9ea-4141-a42e-6e82f8af0133", "children": ["b458c7b8-9fa5-4e93-be90-a196142c0239"], "befores": [{"name": "_Class__pytest_setup_class", "status": "broken", "statusDetails": {"message": "urllib3.exceptions.MaxRetryError: HTTPConnectionPool(host='10.112.162.106', port=4723): Max retries exceeded with url: /wd/hub/session (Caused by NewConnectionError('<urllib3.connection.HTTPConnection object at 0x08C1B7F0>: Failed to establish a new connection: [WinError 10060] 由于连接方在一段时间后没有正确答复或连接的主机没有反应，连接尝试失败。',))\n", "trace": "  File \"c:\\python36-32\\lib\\site-packages\\pluggy\\callers.py\", line 187, in _multicall\n    res = hook_impl.function(*args)\n  File \"c:\\python36-32\\lib\\site-packages\\_pytest\\fixtures.py\", line 923, in pytest_fixture_setup\n    result = call_fixture_func(fixturefunc, request, kwargs)\n  File \"c:\\python36-32\\lib\\site-packages\\_pytest\\fixtures.py\", line 779, in call_fixture_func\n    res = next(it)\n  File \"c:\\python36-32\\lib\\site-packages\\_pytest\\python.py\", line 747, in xunit_setup_class_fixture\n    _call_with_optional_argument(func, self.obj)\n  File \"c:\\python36-32\\lib\\site-packages\\_pytest\\python.py\", line 686, in _call_with_optional_argument\n    func(arg)\n  File \"C:\\Users\\yan.wang\\PycharmProjects\\AutomationTest\\cases\\app_ui\\android\\demoProject\\test_index_page.py\", line 9, in setup_class\n    self.demoProjectClient = APP_UI_Android_demoProject_Client()\n  File \"C:\\Users\\yan.wang\\PycharmProjects\\AutomationTest\\base\\app_ui\\android\\demoProject\\app_ui_android_demoProject_client.py\", line 20, in __init__\n    self.driver = webdriver.Remote(self.config.appium_hub,desired_capabilities=self.demoProjectConfig.get_desired_capabilities())\n  File \"c:\\python36-32\\lib\\site-packages\\appium\\webdriver\\webdriver.py\", line 97, in __init__\n    super(WebDriver, self).__init__(command_executor, desired_capabilities, browser_profile, proxy, keep_alive)\n  File \"c:\\python36-32\\lib\\site-packages\\selenium\\webdriver\\remote\\webdriver.py\", line 156, in __init__\n    self.start_session(capabilities, browser_profile)\n  File \"c:\\python36-32\\lib\\site-packages\\appium\\webdriver\\webdriver.py\", line 136, in start_session\n    response = self.execute(RemoteCommand.NEW_SESSION, parameters)\n  File \"c:\\python36-32\\lib\\site-packages\\selenium\\webdriver\\remote\\webdriver.py\", line 318, in execute\n    response = self.command_executor.execute(driver_command, params)\n  File \"c:\\python36-32\\lib\\site-packages\\selenium\\webdriver\\remote\\remote_connection.py\", line 375, in execute\n    return self._request(command_info[0], url, body=data)\n  File \"c:\\python36-32\\lib\\site-packages\\selenium\\webdriver\\remote\\remote_connection.py\", line 402, in _request\n    resp = http.request(method, url, body=body, headers=headers)\n  File \"c:\\python36-32\\lib\\site-packages\\urllib3\\request.py\", line 70, in request\n    **urlopen_kw)\n  File \"c:\\python36-32\\lib\\site-packages\\urllib3\\request.py\", line 148, in request_encode_body\n    return self.urlopen(method, url, **extra_kw)\n  File \"c:\\python36-32\\lib\\site-packages\\urllib3\\poolmanager.py\", line 321, in urlopen\n    response = conn.urlopen(method, u.request_uri, **kw)\n  File \"c:\\python36-32\\lib\\site-packages\\urllib3\\connectionpool.py\", line 668, in urlopen\n    **response_kw)\n  File \"c:\\python36-32\\lib\\site-packages\\urllib3\\connectionpool.py\", line 668, in urlopen\n    **response_kw)\n  File \"c:\\python36-32\\lib\\site-packages\\urllib3\\connectionpool.py\", line 668, in urlopen\n    **response_kw)\n  File \"c:\\python36-32\\lib\\site-packages\\urllib3\\connectionpool.py\", line 639, in urlopen\n    _stacktrace=sys.exc_info()[2])\n  File \"c:\\python36-32\\lib\\site-packages\\urllib3\\util\\retry.py\", line 388, in increment\n    raise MaxRetryError(_pool, url, error or ResponseError(cause))\n"}, "start": 1576225664232, "stop": 1576225749283}], "start": 1576225664232, "stop": 1576225749904}